Workbook

Sheet Calculation
A1: Product name | D1: portion | E1: 7 | G1: Product name | J1: portion | M1: Product name | P1: portion | S1: Product name | V1: portion | Y1: Product name | AB1: portion | AE1: Product name | AH1: portion | AK1: Product name | AN1: portion | AQ1: Product name | AT1: portion | AW1: Product name | AZ1: portion | BC1: Product name | BF1: portion | BI1: Product name | BL1: portion
A3: # | B3: Grocery | C3: Quantity | D3: price | G3: # | H3: Grocery | I3: Quantity | J3: price | M3: # | N3: Grocery | O3: Quantity | P3: price | S3: # | T3: Grocery | U3: Quantity | V3: price | Y3: # | Z3: Grocery | AA3: Quantity | AB3: price | AE3: # | AF3: Grocery | AG3: Quantity | AH3: price | AK3: # | AL3: Grocery | AM3: Quantity | AN3: price | AQ3: # | AR3: Grocery | AS3: Quantity | AT3: price | AW3: # | AX3: Grocery | AY3: Quantity | AZ3: price | BC3: # | BD3: Grocery | BE3: Quantity | BF3: price | BI3: # | BJ3: Grocery | BK3: Quantity | BL3: price
A4: 1 | D4: =IFERROR(C4 * VLOOKUP(B4, settings!$A$2:$F$500, 4, FALSE), 0) -> 0 | G4: 1 | J4: =IFERROR(I4 * VLOOKUP(H4, settings!$A$2:$F$500, 4, FALSE), 0) -> 0 | M4: 1 | P4: =IFERROR(O4 * VLOOKUP(N4, settings!$A$2:$F$500, 4, FALSE), 0) -> 0 | S4: 1 | V4: =IFERROR(U4 * VLOOKUP(T4, settings!$A$2:$F$500, 4, FALSE), 0) -> 0 | Y4: 1 | AB4: =IFERROR(AA4 * VLOOKUP(Z4, settings!$A$2:$F$500, 4, FALSE), 0) -> 0 | AE4: 1 | AH4: =IFERROR(AG4 * VLOOKUP(AF4, settings!$A$2:$F$500, 4, FALSE), 0) -> 0 | AK4: 1 | AN4: =IFERROR(AM4 * VLOOKUP(AL4, settings!$A$2:$F$500, 4, FALSE), 0) -> 0 | AQ4: 1 | AT4: =IFERROR(AS4 * VLOOKUP(AR4, settings!$A$2:$F$500, 4, FALSE), 0) -> 0 | AW4: 1 | AZ4: =IFERROR(AY4 * VLOOKUP(AX4, settings!$A$2:$F$500, 4, FALSE), 0) -> 0 | BC4: 1 | BF4: =IFERROR(BE4 * VLOOKUP(BD4, settings!$A$2:$F$500, 4, FALSE), 0) -> 0 | BI4: 1 | BL4: =IFERROR(BK4 * VLOOKUP(BJ4, settings!$A$2:$F$500, 4, FALSE), 0) -> 0
A5: 2 | D5: =IFERROR(C5 * VLOOKUP(B5, settings!$A$2:$F$500, 4, FALSE), 0) -> 0 | G5: 2 | J5: =IFERROR(I5 * VLOOKUP(H5, settings!$A$2:$F$500, 4, FALSE), 0) -> 0 | M5: 2 | P5: =IFERROR(O5 * VLOOKUP(N5, settings!$A$2:$F$500, 4, FALSE), 0) -> 0 | S5: 2 | V5: =IFERROR(U5 * VLOOKUP(T5, settings!$A$2:$F$500, 4, FALSE), 0) -> 0 | Y5: 2 | AB5: =IFERROR(AA5 * VLOOKUP(Z5, settings!$A$2:$F$500, 4, FALSE), 0) -> 0 | AE5: 2 | AH5: =IFERROR(AG5 * VLOOKUP(AF5, settings!$A$2:$F$500, 4, FALSE), 0) -> 0 | AK5: 2 | AN5: =IFERROR(AM5 * VLOOKUP(AL5, settings!$A$2:$F$500, 4, FALSE), 0) -> 0 | AQ5: 2 | AT5: =IFERROR(AS5 * VLOOKUP(AR5, settings!$A$2:$F$500, 4, FALSE), 0) -> 0 | AW5: 2 | AZ5: =IFERROR(AY5 * VLOOKUP(AX5, settings!$A$2:$F$500, 4, FALSE), 0) -> 0 | BC5: 2 | BF5: =IFERROR(BE5 * VLOOKUP(BD5, settings!$A$2:$F$500, 4, FALSE), 0) -> 0 | BI5: 2 | BL5: =IFERROR(BK5 * VLOOKUP(BJ5, settings!$A$2:$F$500, 4, FALSE), 0) -> 0
A6: 3 | D6: =IFERROR(C6 * VLOOKUP(B6, settings!$A$2:$F$500, 4, FALSE), 0) -> 0 | G6: 3 | J6: =IFERROR(I6 * VLOOKUP(H6, settings!$A$2:$F$500, 4, FALSE), 0) -> 0 | M6: 3 | P6: =IFERROR(O6 * VLOOKUP(N6, settings!$A$2:$F$500, 4, FALSE), 0) -> 0 | S6: 3 | V6: =IFERROR(U6 * VLOOKUP(T6, settings!$A$2:$F$500, 4, FALSE), 0) -> 0 | Y6: 3 | AB6: =IFERROR(AA6 * VLOOKUP(Z6, settings!$A$2:$F$500, 4, FALSE), 0) -> 0 | AE6: 3 | AH6: =IFERROR(AG6 * VLOOKUP(AF6, settings!$A$2:$F$500, 4, FALSE), 0) -> 0 | AK6: 3 | AN6: =IFERROR(AM6 * VLOOKUP(AL6, settings!$A$2:$F$500, 4, FALSE), 0) -> 0 | AQ6: 3 | AT6: =IFERROR(AS6 * VLOOKUP(AR6, settings!$A$2:$F$500, 4, FALSE), 0) -> 0 | AW6: 3 | AZ6: =IFERROR(AY6 * VLOOKUP(AX6, settings!$A$2:$F$500, 4, FALSE), 0) -> 0 | BC6: 3 | BF6: =IFERROR(BE6 * VLOOKUP(BD6, settings!$A$2:$F$500, 4, FALSE), 0) -> 0 | BI6: 3 | BL6: =IFERROR(BK6 * VLOOKUP(BJ6, settings!$A$2:$F$500, 4, FALSE), 0) -> 0
A7: 4 | D7: =IFERROR(C7 * VLOOKUP(B7, settings!$A$2:$F$500, 4, FALSE), 0) -> 0 | G7: 4 | J7: =IFERROR(I7 * VLOOKUP(H7, settings!$A$2:$F$500, 4, FALSE), 0) -> 0 | M7: 4 | P7: =IFERROR(O7 * VLOOKUP(N7, settings!$A$2:$F$500, 4, FALSE), 0) -> 0 | S7: 4 | V7: =IFERROR(U7 * VLOOKUP(T7, settings!$A$2:$F$500, 4, FALSE), 0) -> 0 | Y7: 4 | AB7: =IFERROR(AA7 * VLOOKUP(Z7, settings!$A$2:$F$500, 4, FALSE), 0) -> 0 | AE7: 4 | AH7: =IFERROR(AG7 * VLOOKUP(AF7, settings!$A$2:$F$500, 4, FALSE), 0) -> 0 | AK7: 4 | AN7: =IFERROR(AM7 * VLOOKUP(AL7, settings!$A$2:$F$500, 4, FALSE), 0) -> 0 | AQ7: 4 | AT7: =IFERROR(AS7 * VLOOKUP(AR7, settings!$A$2:$F$500, 4, FALSE), 0) -> 0 | AW7: 4 | AZ7: =IFERROR(AY7 * VLOOKUP(AX7, settings!$A$2:$F$500, 4, FALSE), 0) -> 0 | BC7: 4 | BF7: =IFERROR(BE7 * VLOOKUP(BD7, settings!$A$2:$F$500, 4, FALSE), 0) -> 0 | BI7: 4 | BL7: =IFERROR(BK7 * VLOOKUP(BJ7, settings!$A$2:$F$500, 4, FALSE), 0) -> 0
A8: 5 | D8: =IFERROR(C8 * VLOOKUP(B8, settings!$A$2:$F$500, 4, FALSE), 0) -> 0 | G8: 5 | J8: =IFERROR(I8 * VLOOKUP(H8, settings!$A$2:$F$500, 4, FALSE), 0) -> 0 | M8: 5 | P8: =IFERROR(O8 * VLOOKUP(N8, settings!$A$2:$F$500, 4, FALSE), 0) -> 0 | S8: 5 | V8: =IFERROR(U8 * VLOOKUP(T8, settings!$A$2:$F$500, 4, FALSE), 0) -> 0 | Y8: 5 | AB8: =IFERROR(AA8 * VLOOKUP(Z8, settings!$A$2:$F$500, 4, FALSE), 0) -> 0 | AE8: 5 | AH8: =IFERROR(AG8 * VLOOKUP(AF8, settings!$A$2:$F$500, 4, FALSE), 0) -> 0 | AK8: 5 | AN8: =IFERROR(AM8 * VLOOKUP(AL8, settings!$A$2:$F$500, 4, FALSE), 0) -> 0 | AQ8: 5 | AT8: =IFERROR(AS8 * VLOOKUP(AR8, settings!$A$2:$F$500, 4, FALSE), 0) -> 0 | AW8: 5 | AZ8: =IFERROR(AY8 * VLOOKUP(AX8, settings!$A$2:$F$500, 4, FALSE), 0) -> 0 | BC8: 5 | BF8: =IFERROR(BE8 * VLOOKUP(BD8, settings!$A$2:$F$500, 4, FALSE), 0) -> 0 | BI8: 5 | BL8: =IFERROR(BK8 * VLOOKUP(BJ8, settings!$A$2:$F$500, 4, FALSE), 0) -> 0
A9: 6 | D9: =IFERROR(C9 * VLOOKUP(B9, settings!$A$2:$F$500, 4, FALSE), 0) -> 0 | G9: 6 | J9: =IFERROR(I9 * VLOOKUP(H9, settings!$A$2:$F$500, 4, FALSE), 0) -> 0 | M9: 6 | P9: =IFERROR(O9 * VLOOKUP(N9, settings!$A$2:$F$500, 4, FALSE), 0) -> 0 | S9: 6 | V9: =IFERROR(U9 * VLOOKUP(T9, settings!$A$2:$F$500, 4, FALSE), 0) -> 0 | Y9: 6 | AB9: =IFERROR(AA9 * VLOOKUP(Z9, settings!$A$2:$F$500, 4, FALSE), 0) -> 0 | AE9: 6 | AH9: =IFERROR(AG9 * VLOOKUP(AF9, settings!$A$2:$F$500, 4, FALSE), 0) -> 0 | AK9: 6 | AN9: =IFERROR(AM9 * VLOOKUP(AL9, settings!$A$2:$F$500, 4, FALSE), 0) -> 0 | AQ9: 6 | AT9: =IFERROR(AS9 * VLOOKUP(AR9, settings!$A$2:$F$500, 4, FALSE), 0) -> 0 | AW9: 6 | AZ9: =IFERROR(AY9 * VLOOKUP(AX9, settings!$A$2:$F$500, 4, FALSE), 0) -> 0 | BC9: 6 | BF9: =IFERROR(BE9 * VLOOKUP(BD9, settings!$A$2:$F$500, 4, FALSE), 0) -> 0 | BI9: 6 | BL9: =IFERROR(BK9 * VLOOKUP(BJ9, settings!$A$2:$F$500, 4, FALSE), 0) -> 0
A10: 7 | D10: =IFERROR(C10 * VLOOKUP(B10, settings!$A$2:$F$500, 4, FALSE), 0) -> 0 | G10: 7 | J10: =IFERROR(I10 * VLOOKUP(H10, settings!$A$2:$F$500, 4, FALSE), 0) -> 0 | M10: 7 | P10: =IFERROR(O10 * VLOOKUP(N10, settings!$A$2:$F$500, 4, FALSE), 0) -> 0 | S10: 7 | V10: =IFERROR(U10 * VLOOKUP(T10, settings!$A$2:$F$500, 4, FALSE), 0) -> 0 | Y10: 7 | AB10: =IFERROR(AA10 * VLOOKUP(Z10, settings!$A$2:$F$500, 4, FALSE), 0) -> 0 | AE10: 7 | AH10: =IFERROR(AG10 * VLOOKUP(AF10, settings!$A$2:$F$500, 4, FALSE), 0) -> 0 | AK10: 7 | AN10: =IFERROR(AM10 * VLOOKUP(AL10, settings!$A$2:$F$500, 4, FALSE), 0) -> 0 | AQ10: 7 | AT10: =IFERROR(AS10 * VLOOKUP(AR10, settings!$A$2:$F$500, 4, FALSE), 0) -> 0 | AW10: 7 | AZ10: =IFERROR(AY10 * VLOOKUP(AX10, settings!$A$2:$F$500, 4, FALSE), 0) -> 0 | BC10: 7 | BF10: =IFERROR(BE10 * VLOOKUP(BD10, settings!$A$2:$F$500, 4, FALSE), 0) -> 0 | BI10: 7 | BL10: =IFERROR(BK10 * VLOOKUP(BJ10, settings!$A$2:$F$500, 4, FALSE), 0) -> 0
A11: 8 | D11: =IFERROR(C11 * VLOOKUP(B11, settings!$A$2:$F$500, 4, FALSE), 0) -> 0 | G11: 8 | J11: =IFERROR(I11 * VLOOKUP(H11, settings!$A$2:$F$500, 4, FALSE), 0) -> 0 | M11: 8 | P11: =IFERROR(O11 * VLOOKUP(N11, settings!$A$2:$F$500, 4, FALSE), 0) -> 0 | S11: 8 | V11: =IFERROR(U11 * VLOOKUP(T11, settings!$A$2:$F$500, 4, FALSE), 0) -> 0 | Y11: 8 | AB11: =IFERROR(AA11 * VLOOKUP(Z11, settings!$A$2:$F$500, 4, FALSE), 0) -> 0 | AE11: 8 | AH11: =IFERROR(AG11 * VLOOKUP(AF11, settings!$A$2:$F$500, 4, FALSE), 0) -> 0 | AK11: 8 | AN11: =IFERROR(AM11 * VLOOKUP(AL11, settings!$A$2:$F$500, 4, FALSE), 0) -> 0 | AQ11: 8 | AT11: =IFERROR(AS11 * VLOOKUP(AR11, settings!$A$2:$F$500, 4, FALSE), 0) -> 0 | AW11: 8 | AZ11: =IFERROR(AY11 * VLOOKUP(AX11, settings!$A$2:$F$500, 4, FALSE), 0) -> 0 | BC11: 8 | BF11: =IFERROR(BE11 * VLOOKUP(BD11, settings!$A$2:$F$500, 4, FALSE), 0) -> 0 | BI11: 8 | BL11: =IFERROR(BK11 * VLOOKUP(BJ11, settings!$A$2:$F$500, 4, FALSE), 0) -> 0
A12: 9 | D12: =IFERROR(C12 * VLOOKUP(B12, settings!$A$2:$F$500, 4, FALSE), 0) -> 0 | G12: 9 | J12: =IFERROR(I12 * VLOOKUP(H12, settings!$A$2:$F$500, 4, FALSE), 0) -> 0 | M12: 9 | P12: =IFERROR(O12 * VLOOKUP(N12, settings!$A$2:$F$500, 4, FALSE), 0) -> 0 | S12: 9 | V12: =IFERROR(U12 * VLOOKUP(T12, settings!$A$2:$F$500, 4, FALSE), 0) -> 0 | Y12: 9 | AB12: =IFERROR(AA12 * VLOOKUP(Z12, settings!$A$2:$F$500, 4, FALSE), 0) -> 0 | AE12: 9 | AH12: =IFERROR(AG12 * VLOOKUP(AF12, settings!$A$2:$F$500, 4, FALSE), 0) -> 0 | AK12: 9 | AN12: =IFERROR(AM12 * VLOOKUP(AL12, settings!$A$2:$F$500, 4, FALSE), 0) -> 0 | AQ12: 9 | AT12: =IFERROR(AS12 * VLOOKUP(AR12, settings!$A$2:$F$500, 4, FALSE), 0) -> 0 | AW12: 9 | AZ12: =IFERROR(AY12 * VLOOKUP(AX12, settings!$A$2:$F$500, 4, FALSE), 0) -> 0 | BC12: 9 | BF12: =IFERROR(BE12 * VLOOKUP(BD12, settings!$A$2:$F$500, 4, FALSE), 0) -> 0 | BI12: 9 | BL12: =IFERROR(BK12 * VLOOKUP(BJ12, settings!$A$2:$F$500, 4, FALSE), 0) -> 0
A13: 10 | D13: =IFERROR(C13 * VLOOKUP(B13, settings!$A$2:$F$500, 4, FALSE), 0) -> 0 | G13: 10 | J13: =IFERROR(I13 * VLOOKUP(H13, settings!$A$2:$F$500, 4, FALSE), 0) -> 0 | M13: 10 | P13: =IFERROR(O13 * VLOOKUP(N13, settings!$A$2:$F$500, 4, FALSE), 0) -> 0 | S13: 10 | V13: =IFERROR(U13 * VLOOKUP(T13, settings!$A$2:$F$500, 4, FALSE), 0) -> 0 | Y13: 10 | AB13: =IFERROR(AA13 * VLOOKUP(Z13, settings!$A$2:$F$500, 4, FALSE), 0) -> 0 | AE13: 10 | AH13: =IFERROR(AG13 * VLOOKUP(AF13, settings!$A$2:$F$500, 4, FALSE), 0) -> 0 | AK13: 10 | AN13: =IFERROR(AM13 * VLOOKUP(AL13, settings!$A$2:$F$500, 4, FALSE), 0) -> 0 | AQ13: 10 | AT13: =IFERROR(AS13 * VLOOKUP(AR13, settings!$A$2:$F$500, 4, FALSE), 0) -> 0 | AW13: 10 | AZ13: =IFERROR(AY13 * VLOOKUP(AX13, settings!$A$2:$F$500, 4, FALSE), 0) -> 0 | BC13: 10 | BF13: =IFERROR(BE13 * VLOOKUP(BD13, settings!$A$2:$F$500, 4, FALSE), 0) -> 0 | BI13: 10 | BL13: =IFERROR(BK13 * VLOOKUP(BJ13, settings!$A$2:$F$500, 4, FALSE), 0) -> 0
A14: 11 | D14: =IFERROR(C14 * VLOOKUP(B14, settings!$A$2:$F$500, 4, FALSE), 0) -> 0 | G14: 11 | J14: =IFERROR(I14 * VLOOKUP(H14, settings!$A$2:$F$500, 4, FALSE), 0) -> 0 | M14: 11 | P14: =IFERROR(O14 * VLOOKUP(N14, settings!$A$2:$F$500, 4, FALSE), 0) -> 0 | S14: 11 | V14: =IFERROR(U14 * VLOOKUP(T14, settings!$A$2:$F$500, 4, FALSE), 0) -> 0 | Y14: 11 | AB14: =IFERROR(AA14 * VLOOKUP(Z14, settings!$A$2:$F$500, 4, FALSE), 0) -> 0 | AE14: 11 | AH14: =IFERROR(AG14 * VLOOKUP(AF14, settings!$A$2:$F$500, 4, FALSE), 0) -> 0 | AK14: 11 | AN14: =IFERROR(AM14 * VLOOKUP(AL14, settings!$A$2:$F$500, 4, FALSE), 0) -> 0 | AQ14: 11 | AT14: =IFERROR(AS14 * VLOOKUP(AR14, settings!$A$2:$F$500, 4, FALSE), 0) -> 0 | AW14: 11 | AZ14: =IFERROR(AY14 * VLOOKUP(AX14, settings!$A$2:$F$500, 4, FALSE), 0) -> 0 | BC14: 11 | BF14: =IFERROR(BE14 * VLOOKUP(BD14, settings!$A$2:$F$500, 4, FALSE), 0) -> 0 | BI14: 11 | BL14: =IFERROR(BK14 * VLOOKUP(BJ14, settings!$A$2:$F$500, 4, FALSE), 0) -> 0
A15: 12 | D15: =IFERROR(C15 * VLOOKUP(B15, settings!$A$2:$F$500, 4, FALSE), 0) -> 0 | G15: 12 | J15: =IFERROR(I15 * VLOOKUP(H15, settings!$A$2:$F$500, 4, FALSE), 0) -> 0 | M15: 12 | P15: =IFERROR(O15 * VLOOKUP(N15, settings!$A$2:$F$500, 4, FALSE), 0) -> 0 | S15: 12 | V15: =IFERROR(U15 * VLOOKUP(T15, settings!$A$2:$F$500, 4, FALSE), 0) -> 0 | Y15: 12 | AB15: =IFERROR(AA15 * VLOOKUP(Z15, settings!$A$2:$F$500, 4, FALSE), 0) -> 0 | AE15: 12 | AH15: =IFERROR(AG15 * VLOOKUP(AF15, settings!$A$2:$F$500, 4, FALSE), 0) -> 0 | AK15: 12 | AN15: =IFERROR(AM15 * VLOOKUP(AL15, settings!$A$2:$F$500, 4, FALSE), 0) -> 0 | AQ15: 12 | AT15: =IFERROR(AS15 * VLOOKUP(AR15, settings!$A$2:$F$500, 4, FALSE), 0) -> 0 | AW15: 12 | AZ15: =IFERROR(AY15 * VLOOKUP(AX15, settings!$A$2:$F$500, 4, FALSE), 0) -> 0 | BC15: 12 | BF15: =IFERROR(BE15 * VLOOKUP(BD15, settings!$A$2:$F$500, 4, FALSE), 0) -> 0 | BI15: 12 | BL15: =IFERROR(BK15 * VLOOKUP(BJ15, settings!$A$2:$F$500, 4, FALSE), 0) -> 0
... A18: 15 | D18: =IFERROR(C18 * VLOOKUP(B18, settings!$A$2:$F$500, 4, FALSE), 0) -> 0 | G18: 15 | J18: =IFERROR(I18 * VLOOKUP(H18, settings!$A$2:$F$500, 4, FALSE), 0) -> 0 | M18: 15 | P18: =IFERROR(O18 * VLOOKUP(N18, settings!$A$2:$F$500, 4, FALSE), 0) -> 0 | S18: 15 | V18: =IFERROR(U18 * VLOOKUP(T18, settings!$A$2:$F$500, 4, FALSE), 0) -> 0 | Y18: 15 | AB18: =IFERROR(AA18 * VLOOKUP(Z18, settings!$A$2:$F$500, 4, FALSE), 0) -> 0 | AE18: 15 | AH18: =IFERROR(AG18 * VLOOKUP(AF18, settings!$A$2:$F$500, 4, FALSE), 0) -> 0 | AK18: 15 | AN18: =IFERROR(AM18 * VLOOKUP(AL18, settings!$A$2:$F$500, 4, FALSE), 0) -> 0 | AQ18: 15 | AT18: =IFERROR(AS18 * VLOOKUP(AR18, settings!$A$2:$F$500, 4, FALSE), 0) -> 0 | AW18: 15 | AZ18: =IFERROR(AY18 * VLOOKUP(AX18, settings!$A$2:$F$500, 4, FALSE), 0) -> 0 | BC18: 15 | BF18: =IFERROR(BE18 * VLOOKUP(BD18, settings!$A$2:$F$500, 4, FALSE), 0) -> 0 | BI18: 15 | BL18: =IFERROR(BK18 * VLOOKUP(BJ18, settings!$A$2:$F$500, 4, FALSE), 0) -> 0
D19: depreciation(%) | J19: depreciation(%) | P19: depreciation(%) | V19: depreciation(%) | AB19: depreciation(%) | AH19: depreciation(%) | AN19: depreciation(%) | AT19: depreciation(%) | AZ19: depreciation(%) | BF19: depreciation(%) | BL19: depreciation(%)
D20: Work(%) | J20: Work(%) | P20: Work(%) | V20: Work(%) | AB20: Work(%) | AH20: Work(%) | AN20: Work(%) | AT20: Work(%) | AZ20: Work(%) | BF20: Work(%) | BL20: Work(%)
D21: Work + deprec. | E21: =SUM(D4:D18) * (E19 + E20) -> 0 | J21: Work + deprec. | K21: =SUM(J4:J18) * (K19 + K20) -> 0 | P21: Work + deprec. | Q21: =SUM(P4:P18) * (Q19 + Q20) -> 0 | V21: Work + deprec. | W21: =SUM(V4:V18) * (W19 + W20) -> 0 | AB21: Work + deprec. | AC21: =SUM(AB4:AB18) * (AC19 + AC20) -> 0 | AH21: Work + deprec. | AI21: =SUM(AH4:AH18) * (AI19 + AI20) -> 0 | AN21: Work + deprec. | AO21: =SUM(AN4:AN18) * (AO19 + AO20) -> 0 | AT21: Work + deprec. | AU21: =SUM(AT4:AT18) * (AU19 + AU20) -> 0 | AZ21: Work + deprec. | BA21: =SUM(AZ4:AZ18) * (BA19 + BA20) -> 0 | BF21: Work + deprec. | BG21: =SUM(BF4:BF18) * (BG19 + BG20) -> 0 | BL21: Work + deprec. | BM21: =SUM(BL4:BL18) * (BM19 + BM20) -> 0
D22: Total Price | E22: =SUM(D4:D18) + E21 -> 0 | J22: Total Price | K22: =SUM(J4:J18) + K21 -> 0 | P22: Total Price | Q22: =SUM(P4:P18) + Q21 -> 0 | V22: Total Price | W22: =SUM(V4:V18) + W21 -> 0 | AB22: Total Price | AC22: =SUM(AB4:AB18) + AC21 -> 0 | AH22: Total Price | AI22: =SUM(AH4:AH18) + AI21 -> 0 | AN22: Total Price | AO22: =SUM(AN4:AN18) + AO21 -> 0 | AT22: Total Price | AU22: =SUM(AT4:AT18) + AU21 -> 0 | AZ22: Total Price | BA22: =SUM(AZ4:AZ18) + BA21 -> 0 | BF22: Total Price | BG22: =SUM(BF4:BF18) + BG21 -> 0 | BL22: Total Price | BM22: =SUM(BL4:BL18) + BM21 -> 0
D23: Price per 1 | E23: =IF(E1 > 0, E22 / E1, 0) -> 0 | J23: Price per 1 | K23: =IF(K1 > 0, K22 / K1, 0) -> 0 | P23: Price per 1 | Q23: =IF(Q1 > 0, Q22 / Q1, 0) -> 0 | V23: Price per 1 | W23: =IF(W1 > 0, W22 / W1, 0) -> 0 | AB23: Price per 1 | AC23: =IF(AC1 > 0, AC22 / AC1, 0) -> 0 | AH23: Price per 1 | AI23: =IF(AI1 > 0, AI22 / AI1, 0) -> 0 | AN23: Price per 1 | AO23: =IF(AO1 > 0, AO22 / AO1, 0) -> 0 | AT23: Price per 1 | AU23: =IF(AU1 > 0, AU22 / AU1, 0) -> 0 | AZ23: Price per 1 | BA23: =IF(BA1 > 0, BA22 / BA1, 0) -> 0 | BF23: Price per 1 | BG23: =IF(BG1 > 0, BG22 / BG1, 0) -> 0 | BL23: Price per 1 | BM23: =IF(BM1 > 0, BM22 / BM1, 0) -> 0
A25: Product name | D25: portion | G25: Product name | J25: portion | M25: Product name | P25: portion | S25: Product name | V25: portion | Y25: Product name | AB25: portion | AE25: Product name | AH25: portion | AK25: Product name | AN25: portion | AQ25: Product name | AT25: portion | AW25: Product name | AZ25: portion | BC25: Product name | BF25: portion | BI25: Product name | BL25: portion
A27: # | B27: Grocery | C27: Quantity | D27: price | G27: # | H27: Grocery | I27: Quantity | J27: price | M27: # | N27: Grocery | O27: Quantity | P27: price | S27: # | T27: Grocery | U27: Quantity | V27: price | Y27: # | Z27: Grocery | AA27: Quantity | AB27: price | AE27: # | AF27: Grocery | AG27: Quantity | AH27: price | AK27: # | AL27: Grocery | AM27: Quantity | AN27: price | AQ27: # | AR27: Grocery | AS27: Quantity | AT27: price | AW27: # | AX27: Grocery | AY27: Quantity | AZ27: price | BC27: # | BD27: Grocery | BE27: Quantity | BF27: price | BI27: # | BJ27: Grocery | BK27: Quantity | BL27: price
A28: 1 | D28: =IFERROR(C28 * VLOOKUP(B28, settings!$A$2:$F$500, 4, FALSE), 0) -> 0 | G28: 1 | J28: =IFERROR(I28 * VLOOKUP(H28, settings!$A$2:$F$500, 4, FALSE), 0) -> 0 | M28: 1 | P28: =IFERROR(O28 * VLOOKUP(N28, settings!$A$2:$F$500, 4, FALSE), 0) -> 0 | S28: 1 | V28: =IFERROR(U28 * VLOOKUP(T28, settings!$A$2:$F$500, 4, FALSE), 0) -> 0 | Y28: 1 | AB28: =IFERROR(AA28 * VLOOKUP(Z28, settings!$A$2:$F$500, 4, FALSE), 0) -> 0 | AE28: 1 | AH28: =IFERROR(AG28 * VLOOKUP(AF28, settings!$A$2:$F$500, 4, FALSE), 0) -> 0 | AK28: 1 | AN28: =IFERROR(AM28 * VLOOKUP(AL28, settings!$A$2:$F$500, 4, FALSE), 0) -> 0 | AQ28: 1 | AT28: =IFERROR(AS28 * VLOOKUP(AR28, settings!$A$2:$F$500, 4, FALSE), 0) -> 0 | AW28: 1 | AZ28: =IFERROR(AY28 * VLOOKUP(AX28, settings!$A$2:$F$500, 4, FALSE), 0) -> 0 | BC28: 1 | BF28: =IFERROR(BE28 * VLOOKUP(BD28, settings!$A$2:$F$500, 4, FALSE), 0) -> 0 | BI28: 1 | BL28: =IFERROR(BK28 * VLOOKUP(BJ28, settings!$A$2:$F$500, 4, FALSE), 0) -> 0
A29: 2 | D29: =IFERROR(C29 * VLOOKUP(B29, settings!$A$2:$F$500, 4, FALSE), 0) -> 0 | G29: 2 | J29: =IFERROR(I29 * VLOOKUP(H29, settings!$A$2:$F$500, 4, FALSE), 0) -> 0 | M29: 2 | P29: =IFERROR(O29 * VLOOKUP(N29, settings!$A$2:$F$500, 4, FALSE), 0) -> 0 | S29: 2 | V29: =IFERROR(U29 * VLOOKUP(T29, settings!$A$2:$F$500, 4, FALSE), 0) -> 0 | Y29: 2 | AB29: =IFERROR(AA29 * VLOOKUP(Z29, settings!$A$2:$F$500, 4, FALSE), 0) -> 0 | AE29: 2 | AH29: =IFERROR(AG29 * VLOOKUP(AF29, settings!$A$2:$F$500, 4, FALSE), 0) -> 0 | AK29: 2 | AN29: =IFERROR(AM29 * VLOOKUP(AL29, settings!$A$2:$F$500, 4, FALSE), 0) -> 0 | AQ29: 2 | AT29: =IFERROR(AS29 * VLOOKUP(AR29, settings!$A$2:$F$500, 4, FALSE), 0) -> 0 | AW29: 2 | AZ29: =IFERROR(AY29 * VLOOKUP(AX29, settings!$A$2:$F$500, 4, FALSE), 0) -> 0 | BC29: 2 | BF29: =IFERROR(BE29 * VLOOKUP(BD29, settings!$A$2:$F$500, 4, FALSE), 0) -> 0 | BI29: 2 | BL29: =IFERROR(BK29 * VLOOKUP(BJ29, settings!$A$2:$F$500, 4, FALSE), 0) -> 0
A30: 3 | D30: =IFERROR(C30 * VLOOKUP(B30, settings!$A$2:$F$500, 4, FALSE), 0) -> 0 | G30: 3 | J30: =IFERROR(I30 * VLOOKUP(H30, settings!$A$2:$F$500, 4, FALSE), 0) -> 0 | M30: 3 | P30: =IFERROR(O30 * VLOOKUP(N30, settings!$A$2:$F$500, 4, FALSE), 0) -> 0 | S30: 3 | V30: =IFERROR(U30 * VLOOKUP(T30, settings!$A$2:$F$500, 4, FALSE), 0) -> 0 | Y30: 3 | AB30: =IFERROR(AA30 * VLOOKUP(Z30, settings!$A$2:$F$500, 4, FALSE), 0) -> 0 | AE30: 3 | AH30: =IFERROR(AG30 * VLOOKUP(AF30, settings!$A$2:$F$500, 4, FALSE), 0) -> 0 | AK30: 3 | AN30: =IFERROR(AM30 * VLOOKUP(AL30, settings!$A$2:$F$500, 4, FALSE), 0) -> 0 | AQ30: 3 | AT30: =IFERROR(AS30 * VLOOKUP(AR30, settings!$A$2:$F$500, 4, FALSE), 0) -> 0 | AW30: 3 | AZ30: =IFERROR(AY30 * VLOOKUP(AX30, settings!$A$2:$F$500, 4, FALSE), 0) -> 0 | BC30: 3 | BF30: =IFERROR(BE30 * VLOOKUP(BD30, settings!$A$2:$F$500, 4, FALSE), 0) -> 0 | BI30: 3 | BL30: =IFERROR(BK30 * VLOOKUP(BJ30, settings!$A$2:$F$500, 4, FALSE), 0) -> 0
A31: 4 | D31: =IFERROR(C31 * VLOOKUP(B31, settings!$A$2:$F$500, 4, FALSE), 0) -> 0 | G31: 4 | J31: =IFERROR(I31 * VLOOKUP(H31, settings!$A$2:$F$500, 4, FALSE), 0) -> 0 | M31: 4 | P31: =IFERROR(O31 * VLOOKUP(N31, settings!$A$2:$F$500, 4, FALSE), 0) -> 0 | S31: 4 | V31: =IFERROR(U31 * VLOOKUP(T31, settings!$A$2:$F$500, 4, FALSE), 0) -> 0 | Y31: 4 | AB31: =IFERROR(AA31 * VLOOKUP(Z31, settings!$A$2:$F$500, 4, FALSE), 0) -> 0 | AE31: 4 | AH31: =IFERROR(AG31 * VLOOKUP(AF31, settings!$A$2:$F$500, 4, FALSE), 0) -> 0 | AK31: 4 | AN31: =IFERROR(AM31 * VLOOKUP(AL31, settings!$A$2:$F$500, 4, FALSE), 0) -> 0 | AQ31: 4 | AT31: =IFERROR(AS31 * VLOOKUP(AR31, settings!$A$2:$F$500, 4, FALSE), 0) -> 0 | AW31: 4 | AZ31: =IFERROR(AY31 * VLOOKUP(AX31, settings!$A$2:$F$500, 4, FALSE), 0) -> 0 | BC31: 4 | BF31: =IFERROR(BE31 * VLOOKUP(BD31, settings!$A$2:$F$500, 4, FALSE), 0) -> 0 | BI31: 4 | BL31: =IFERROR(BK31 * VLOOKUP(BJ31, settings!$A$2:$F$500, 4, FALSE), 0) -> 0
A32: 5 | D32: =IFERROR(C32 * VLOOKUP(B32, settings!$A$2:$F$500, 4, FALSE), 0) -> 0 | G32: 5 | J32: =IFERROR(I32 * VLOOKUP(H32, settings!$A$2:$F$500, 4, FALSE), 0) -> 0 | M32: 5 | P32: =IFERROR(O32 * VLOOKUP(N32, settings!$A$2:$F$500, 4, FALSE), 0) -> 0 | S32: 5 | V32: =IFERROR(U32 * VLOOKUP(T32, settings!$A$2:$F$500, 4, FALSE), 0) -> 0 | Y32: 5 | AB32: =IFERROR(AA32 * VLOOKUP(Z32, settings!$A$2:$F$500, 4, FALSE), 0) -> 0 | AE32: 5 | AH32: =IFERROR(AG32 * VLOOKUP(AF32, settings!$A$2:$F$500, 4, FALSE), 0) -> 0 | AK32: 5 | AN32: =IFERROR(AM32 * VLOOKUP(AL32, settings!$A$2:$F$500, 4, FALSE), 0) -> 0 | AQ32: 5 | AT32: =IFERROR(AS32 * VLOOKUP(AR32, settings!$A$2:$F$500, 4, FALSE), 0) -> 0 | AW32: 5 | AZ32: =IFERROR(AY32 * VLOOKUP(AX32, settings!$A$2:$F$500, 4, FALSE), 0) -> 0 | BC32: 5 | BF32: =IFERROR(BE32 * VLOOKUP(BD32, settings!$A$2:$F$500, 4, FALSE), 0) -> 0 | BI32: 5 | BL32: =IFERROR(BK32 * VLOOKUP(BJ32, settings!$A$2:$F$500, 4, FALSE), 0) -> 0
A33: 6 | D33: =IFERROR(C33 * VLOOKUP(B33, settings!$A$2:$F$500, 4, FALSE), 0) -> 0 | G33: 6 | J33: =IFERROR(I33 * VLOOKUP(H33, settings!$A$2:$F$500, 4, FALSE), 0) -> 0 | M33: 6 | P33: =IFERROR(O33 * VLOOKUP(N33, settings!$A$2:$F$500, 4, FALSE), 0) -> 0 | S33: 6 | V33: =IFERROR(U33 * VLOOKUP(T33, settings!$A$2:$F$500, 4, FALSE), 0) -> 0 | Y33: 6 | AB33: =IFERROR(AA33 * VLOOKUP(Z33, settings!$A$2:$F$500, 4, FALSE), 0) -> 0 | AE33: 6 | AH33: =IFERROR(AG33 * VLOOKUP(AF33, settings!$A$2:$F$500, 4, FALSE), 0) -> 0 | AK33: 6 | AN33: =IFERROR(AM33 * VLOOKUP(AL33, settings!$A$2:$F$500, 4, FALSE), 0) -> 0 | AQ33: 6 | AT33: =IFERROR(AS33 * VLOOKUP(AR33, settings!$A$2:$F$500, 4, FALSE), 0) -> 0 | AW33: 6 | AZ33: =IFERROR(AY33 * VLOOKUP(AX33, settings!$A$2:$F$500, 4, FALSE), 0) -> 0 | BC33: 6 | BF33: =IFERROR(BE33 * VLOOKUP(BD33, settings!$A$2:$F$500, 4, FALSE), 0) -> 0 | BI33: 6 | BL33: =IFERROR(BK33 * VLOOKUP(BJ33, settings!$A$2:$F$500, 4, FALSE), 0) -> 0
A34: 7 | D34: =IFERROR(C34 * VLOOKUP(B34, settings!$A$2:$F$500, 4, FALSE), 0) -> 0 | G34: 7 | J34: =IFERROR(I34 * VLOOKUP(H34, settings!$A$2:$F$500, 4, FALSE), 0) -> 0 | M34: 7 | P34: =IFERROR(O34 * VLOOKUP(N34, settings!$A$2:$F$500, 4, FALSE), 0) -> 0 | S34: 7 | V34: =IFERROR(U34 * VLOOKUP(T34, settings!$A$2:$F$500, 4, FALSE), 0) -> 0 | Y34: 7 | AB34: =IFERROR(AA34 * VLOOKUP(Z34, settings!$A$2:$F$500, 4, FALSE), 0) -> 0 | AE34: 7 | AH34: =IFERROR(AG34 * VLOOKUP(AF34, settings!$A$2:$F$500, 4, FALSE), 0) -> 0 | AK34: 7 | AN34: =IFERROR(AM34 * VLOOKUP(AL34, settings!$A$2:$F$500, 4, FALSE), 0) -> 0 | AQ34: 7 | AT34: =IFERROR(AS34 * VLOOKUP(AR34, settings!$A$2:$F$500, 4, FALSE), 0) -> 0 | AW34: 7 | AZ34: =IFERROR(AY34 * VLOOKUP(AX34, settings!$A$2:$F$500, 4, FALSE), 0) -> 0 | BC34: 7 | BF34: =IFERROR(BE34 * VLOOKUP(BD34, settings!$A$2:$F$500, 4, FALSE), 0) -> 0 | BI34: 7 | BL34: =IFERROR(BK34 * VLOOKUP(BJ34, settings!$A$2:$F$500, 4, FALSE), 0) -> 0
A35: 8 | D35: =IFERROR(C35 * VLOOKUP(B35, settings!$A$2:$F$500, 4, FALSE), 0) -> 0 | G35: 8 | J35: =IFERROR(I35 * VLOOKUP(H35, settings!$A$2:$F$500, 4, FALSE), 0) -> 0 | M35: 8 | P35: =IFERROR(O35 * VLOOKUP(N35, settings!$A$2:$F$500, 4, FALSE), 0) -> 0 | S35: 8 | V35: =IFERROR(U35 * VLOOKUP(T35, settings!$A$2:$F$500, 4, FALSE), 0) -> 0 | Y35: 8 | AB35: =IFERROR(AA35 * VLOOKUP(Z35, settings!$A$2:$F$500, 4, FALSE), 0) -> 0 | AE35: 8 | AH35: =IFERROR(AG35 * VLOOKUP(AF35, settings!$A$2:$F$500, 4, FALSE), 0) -> 0 | AK35: 8 | AN35: =IFERROR(AM35 * VLOOKUP(AL35, settings!$A$2:$F$500, 4, FALSE), 0) -> 0 | AQ35: 8 | AT35: =IFERROR(AS35 * VLOOKUP(AR35, settings!$A$2:$F$500, 4, FALSE), 0) -> 0 | AW35: 8 | AZ35: =IFERROR(AY35 * VLOOKUP(AX35, settings!$A$2:$F$500, 4, FALSE), 0) -> 0 | BC35: 8 | BF35: =IFERROR(BE35 * VLOOKUP(BD35, settings!$A$2:$F$500, 4, FALSE), 0) -> 0 | BI35: 8 | BL35: =IFERROR(BK35 * VLOOKUP(BJ35, settings!$A$2:$F$500, 4, FALSE), 0) -> 0
A36: 9 | D36: =IFERROR(C36 * VLOOKUP(B36, settings!$A$2:$F$500, 4, FALSE), 0) -> 0 | G36: 9 | J36: =IFERROR(I36 * VLOOKUP(H36, settings!$A$2:$F$500, 4, FALSE), 0) -> 0 | M36: 9 | P36: =IFERROR(O36 * VLOOKUP(N36, settings!$A$2:$F$500, 4, FALSE), 0) -> 0 | S36: 9 | V36: =IFERROR(U36 * VLOOKUP(T36, settings!$A$2:$F$500, 4, FALSE), 0) -> 0 | Y36: 9 | AB36: =IFERROR(AA36 * VLOOKUP(Z36, settings!$A$2:$F$500, 4, FALSE), 0) -> 0 | AE36: 9 | AH36: =IFERROR(AG36 * VLOOKUP(AF36, settings!$A$2:$F$500, 4, FALSE), 0) -> 0 | AK36: 9 | AN36: =IFERROR(AM36 * VLOOKUP(AL36, settings!$A$2:$F$500, 4, FALSE), 0) -> 0 | AQ36: 9 | AT36: =IFERROR(AS36 * VLOOKUP(AR36, settings!$A$2:$F$500, 4, FALSE), 0) -> 0 | AW36: 9 | AZ36: =IFERROR(AY36 * VLOOKUP(AX36, settings!$A$2:$F$500, 4, FALSE), 0) -> 0 | BC36: 9 | BF36: =IFERROR(BE36 * VLOOKUP(BD36, settings!$A$2:$F$500, 4, FALSE), 0) -> 0 | BI36: 9 | BL36: =IFERROR(BK36 * VLOOKUP(BJ36, settings!$A$2:$F$500, 4, FALSE), 0) -> 0
A37: 10 | D37: =IFERROR(C37 * VLOOKUP(B37, settings!$A$2:$F$500, 4, FALSE), 0) -> 0 | G37: 10 | J37: =IFERROR(I37 * VLOOKUP(H37, settings!$A$2:$F$500, 4, FALSE), 0) -> 0 | M37: 10 | P37: =IFERROR(O37 * VLOOKUP(N37, settings!$A$2:$F$500, 4, FALSE), 0) -> 0 | S37: 10 | V37: =IFERROR(U37 * VLOOKUP(T37, settings!$A$2:$F$500, 4, FALSE), 0) -> 0 | Y37: 10 | AB37: =IFERROR(AA37 * VLOOKUP(Z37, settings!$A$2:$F$500, 4, FALSE), 0) -> 0 | AE37: 10 | AH37: =IFERROR(AG37 * VLOOKUP(AF37, settings!$A$2:$F$500, 4, FALSE), 0) -> 0 | AK37: 10 | AN37: =IFERROR(AM37 * VLOOKUP(AL37, settings!$A$2:$F$500, 4, FALSE), 0) -> 0 | AQ37: 10 | AT37: =IFERROR(AS37 * VLOOKUP(AR37, settings!$A$2:$F$500, 4, FALSE), 0) -> 0 | AW37: 10 | AZ37: =IFERROR(AY37 * VLOOKUP(AX37, settings!$A$2:$F$500, 4, FALSE), 0) -> 0 | BC37: 10 | BF37: =IFERROR(BE37 * VLOOKUP(BD37, settings!$A$2:$F$500, 4, FALSE), 0) -> 0 | BI37: 10 | BL37: =IFERROR(BK37 * VLOOKUP(BJ37, settings!$A$2:$F$500, 4, FALSE), 0) -> 0
A38: 11 | D38: =IFERROR(C38 * VLOOKUP(B38, settings!$A$2:$F$500, 4, FALSE), 0) -> 0 | G38: 11 | J38: =IFERROR(I38 * VLOOKUP(H38, settings!$A$2:$F$500, 4, FALSE), 0) -> 0 | M38: 11 | P38: =IFERROR(O38 * VLOOKUP(N38, settings!$A$2:$F$500, 4, FALSE), 0) -> 0 | S38: 11 | V38: =IFERROR(U38 * VLOOKUP(T38, settings!$A$2:$F$500, 4, FALSE), 0) -> 0 | Y38: 11 | AB38: =IFERROR(AA38 * VLOOKUP(Z38, settings!$A$2:$F$500, 4, FALSE), 0) -> 0 | AE38: 11 | AH38: =IFERROR(AG38 * VLOOKUP(AF38, settings!$A$2:$F$500, 4, FALSE), 0) -> 0 | AK38: 11 | AN38: =IFERROR(AM38 * VLOOKUP(AL38, settings!$A$2:$F$500, 4, FALSE), 0) -> 0 | AQ38: 11 | AT38: =IFERROR(AS38 * VLOOKUP(AR38, settings!$A$2:$F$500, 4, FALSE), 0) -> 0 | AW38: 11 | AZ38: =IFERROR(AY38 * VLOOKUP(AX38, settings!$A$2:$F$500, 4, FALSE), 0) -> 0 | BC38: 11 | BF38: =IFERROR(BE38 * VLOOKUP(BD38, settings!$A$2:$F$500, 4, FALSE), 0) -> 0 | BI38: 11 | BL38: =IFERROR(BK38 * VLOOKUP(BJ38, settings!$A$2:$F$500, 4, FALSE), 0) -> 0
A39: 12 | D39: =IFERROR(C39 * VLOOKUP(B39, settings!$A$2:$F$500, 4, FALSE), 0) -> 0 | G39: 12 | J39: =IFERROR(I39 * VLOOKUP(H39, settings!$A$2:$F$500, 4, FALSE), 0) -> 0 | M39: 12 | P39: =IFERROR(O39 * VLOOKUP(N39, settings!$A$2:$F$500, 4, FALSE), 0) -> 0 | S39: 12 | V39: =IFERROR(U39 * VLOOKUP(T39, settings!$A$2:$F$500, 4, FALSE), 0) -> 0 | Y39: 12 | AB39: =IFERROR(AA39 * VLOOKUP(Z39, settings!$A$2:$F$500, 4, FALSE), 0) -> 0 | AE39: 12 | AH39: =IFERROR(AG39 * VLOOKUP(AF39, settings!$A$2:$F$500, 4, FALSE), 0) -> 0 | AK39: 12 | AN39: =IFERROR(AM39 * VLOOKUP(AL39, settings!$A$2:$F$500, 4, FALSE), 0) -> 0 | AQ39: 12 | AT39: =IFERROR(AS39 * VLOOKUP(AR39, settings!$A$2:$F$500, 4, FALSE), 0) -> 0 | AW39: 12 | AZ39: =IFERROR(AY39 * VLOOKUP(AX39, settings!$A$2:$F$500, 4, FALSE), 0) -> 0 | BC39: 12 | BF39: =IFERROR(BE39 * VLOOKUP(BD39, settings!$A$2:$F$500, 4, FALSE), 0) -> 0 | BI39: 12 | BL39: =IFERROR(BK39 * VLOOKUP(BJ39, settings!$A$2:$F$500, 4, FALSE), 0) -> 0
... A42: 15 | D42: =IFERROR(C42 * VLOOKUP(B42, settings!$A$2:$F$500, 4, FALSE), 0) -> 0 | G42: 15 | J42: =IFERROR(I42 * VLOOKUP(H42, settings!$A$2:$F$500, 4, FALSE), 0) -> 0 | M42: 15 | P42: =IFERROR(O42 * VLOOKUP(N42, settings!$A$2:$F$500, 4, FALSE), 0) -> 0 | S42: 15 | V42: =IFERROR(U42 * VLOOKUP(T42, settings!$A$2:$F$500, 4, FALSE), 0) -> 0 | Y42: 15 | AB42: =IFERROR(AA42 * VLOOKUP(Z42, settings!$A$2:$F$500, 4, FALSE), 0) -> 0 | AE42: 15 | AH42: =IFERROR(AG42 * VLOOKUP(AF42, settings!$A$2:$F$500, 4, FALSE), 0) -> 0 | AK42: 15 | AN42: =IFERROR(AM42 * VLOOKUP(AL42, settings!$A$2:$F$500, 4, FALSE), 0) -> 0 | AQ42: 15 | AT42: =IFERROR(AS42 * VLOOKUP(AR42, settings!$A$2:$F$500, 4, FALSE), 0) -> 0 | AW42: 15 | AZ42: =IFERROR(AY42 * VLOOKUP(AX42, settings!$A$2:$F$500, 4, FALSE), 0) -> 0 | BC42: 15 | BF42: =IFERROR(BE42 * VLOOKUP(BD42, settings!$A$2:$F$500, 4, FALSE), 0) -> 0 | BI42: 15 | BL42: =IFERROR(BK42 * VLOOKUP(BJ42, settings!$A$2:$F$500, 4, FALSE), 0) -> 0
D43: depreciation(%) | J43: depreciation(%) | P43: depreciation(%) | V43: depreciation(%) | AB43: depreciation(%) | AH43: depreciation(%) | AN43: depreciation(%) | AT43: depreciation(%) | AZ43: depreciation(%) | BF43: depreciation(%) | BL43: depreciation(%)
D44: Work(%) | J44: Work(%) | P44: Work(%) | V44: Work(%) | AB44: Work(%) | AH44: Work(%) | AN44: Work(%) | AT44: Work(%) | AZ44: Work(%) | BF44: Work(%) | BL44: Work(%)
D45: Work + deprec. | E45: =SUM(D28:D42) * (E43 + E44) -> 0 | J45: Work + deprec. | K45: =SUM(J28:J42) * (K43 + K44) -> 0 | P45: Work + deprec. | Q45: =SUM(P28:P42) * (Q43 + Q44) -> 0 | V45: Work + deprec. | W45: =SUM(V28:V42) * (W43 + W44) -> 0 | AB45: Work + deprec. | AC45: =SUM(AB28:AB42) * (AC43 + AC44) -> 0 | AH45: Work + deprec. | AI45: =SUM(AH28:AH42) * (AI43 + AI44) -> 0 | AN45: Work + deprec. | AO45: =SUM(AN28:AN42) * (AO43 + AO44) -> 0 | AT45: Work + deprec. | AU45: =SUM(AT28:AT42) * (AU43 + AU44) -> 0 | AZ45: Work + deprec. | BA45: =SUM(AZ28:AZ42) * (BA43 + BA44) -> 0 | BF45: Work + deprec. | BG45: =SUM(BF28:BF42) * (BG43 + BG44) -> 0 | BL45: Work + deprec. | BM45: =SUM(BL28:BL42) * (BM43 + BM44) -> 0
D46: Total Price | E46: =SUM(D28:D42) + E45 -> 0 | J46: Total Price | K46: =SUM(J28:J42) + K45 -> 0 | P46: Total Price | Q46: =SUM(P28:P42) + Q45 -> 0 | V46: Total Price | W46: =SUM(V28:V42) + W45 -> 0 | AB46: Total Price | AC46: =SUM(AB28:AB42) + AC45 -> 0 | AH46: Total Price | AI46: =SUM(AH28:AH42) + AI45 -> 0 | AN46: Total Price | AO46: =SUM(AN28:AN42) + AO45 -> 0 | AT46: Total Price | AU46: =SUM(AT28:AT42) + AU45 -> 0 | AZ46: Total Price | BA46: =SUM(AZ28:AZ42) + BA45 -> 0 | BF46: Total Price | BG46: =SUM(BF28:BF42) + BG45 -> 0 | BL46: Total Price | BM46: =SUM(BL28:BL42) + BM45 -> 0
D47: Price per 1 | E47: =IF(E25 > 0, E46 / E25, 0) -> 0 | J47: Price per 1 | K47: =IF(K25 > 0, K46 / K25, 0) -> 0 | P47: Price per 1 | Q47: =IF(Q25 > 0, Q46 / Q25, 0) -> 0 | V47: Price per 1 | W47: =IF(W25 > 0, W46 / W25, 0) -> 0 | AB47: Price per 1 | AC47: =IF(AC25 > 0, AC46 / AC25, 0) -> 0 | AH47: Price per 1 | AI47: =IF(AI25 > 0, AI46 / AI25, 0) -> 0 | AN47: Price per 1 | AO47: =IF(AO25 > 0, AO46 / AO25, 0) -> 0 | AT47: Price per 1 | AU47: =IF(AU25 > 0, AU46 / AU25, 0) -> 0 | AZ47: Price per 1 | BA47: =IF(BA25 > 0, BA46 / BA25, 0) -> 0 | BF47: Price per 1 | BG47: =IF(BG25 > 0, BG46 / BG25, 0) -> 0 | BL47: Price per 1 | BM47: =IF(BM25 > 0, BM46 / BM25, 0) -> 0
...

Sheet settings
A1: Product | B1: price(per 1 pac) | C1: quantity(g) | D1: price (per 1ml/g) | E1: price (per 100g/ml) | F1: Link on product
D2: =IF(C2>0, B2/C2, 0) -> 0 | E2: =D2*100 -> 0
D3: =IF(C3>0, B3/C3, 0) -> 0 | E3: =D3*100 -> 0
D4: =IF(C4>0, B4/C4, 0) -> 0 | E4: =D4*100 -> 0
D5: =IF(C5>0, B5/C5, 0) -> 0 | E5: =D5*100 -> 0
D6: =IF(C6>0, B6/C6, 0) -> 0 | E6: =D6*100 -> 0
D7: =IF(C7>0, B7/C7, 0) -> 0 | E7: =D7*100 -> 0
D8: =IF(C8>0, B8/C8, 0) -> 0 | E8: =D8*100 -> 0
D9: =IF(C9>0, B9/C9, 0) -> 0 | E9: =D9*100 -> 0
D10: =IF(C10>0, B10/C10, 0) -> 0 | E10: =D10*100 -> 0
D11: =IF(C11>0, B11/C11, 0) -> 0 | E11: =D11*100 -> 0
D12: =IF(C12>0, B12/C12, 0) -> 0 | E12: =D12*100 -> 0
D13: =IF(C13>0, B13/C13, 0) -> 0 | E13: =D13*100 -> 0
... D500: =IF(C500>0, B500/C500, 0) -> 0 | E500: =D500*100 -> 0
